<?xml version="1.0" encoding="utf-8"?>

<robot name="iiwa14">

  <joint name="iiwa_base_joint" type="fixed">
    <origin rpy="0 0 0" xyz="0 0 0"/>
    <parent link="base"/>
    <child link="iiwa_link_0"/>
  </joint>

  <link name="iiwa_link_0">
    <inertial>
      <origin rpy="0 0 0" xyz="0 0 0"/>
      <mass value="5"/>
      <inertia ixx="0.05" ixy="0" ixz="0" iyy="0.06" iyz="0" izz="0.03"/>
    </inertial>
    <visual>
      <origin rpy="0 0 0" xyz="0 0 0"/> 
      <geometry>
        <mesh filename="C:/Users/chiha/OneDrive/Documents/tinyurdf/examples/meshes/link_0.stl"/>
      </geometry>
    </visual>
  </link>

  <joint name="iiwa_joint_1" type="revolute">
    <parent link="iiwa_link_0"/>
    <child link="iiwa_link_1"/>
    <origin rpy="0 0 0" xyz="0 0 0.3"/> 
    <axis xyz="0 0 1"/>
    <limit effort="320" lower="-2.96705972839" upper="2.96705972839" velocity="1.4835298641951802"/>
    <dynamics damping="0.5"/>
  </joint>

  <link name="iiwa_link_1">
    <inertial>
      <origin rpy="0 0 0" xyz="0 0 0"/>
      <mass value="5.76"/>
      <inertia ixx="0.033" ixy="0" ixz="0" iyy="0.0333" iyz="0" izz="0.0123"/>
    </inertial>
    <visual>
      <origin rpy="0 0 0" xyz="0 0 0.3"/> 
      <geometry>
        <mesh filename="C:/Users/chiha/OneDrive/Documents/tinyurdf/examples/meshes/link_1.stl"/>
      </geometry>
    </visual>
  </link>

  <joint name="iiwa_joint_2" type="revolute">
    <parent link="iiwa_link_1"/>
    <child link="iiwa_link_2"/>
    <origin rpy="1.5708 0 3.1416" xyz="0 0 0.7"/> 
    <axis xyz="0 0 1"/>
    <limit drake:acceleration="8.57" effort="320" lower="-2.09439510239" upper="2.09439510239" velocity="1.4835298641951802"/>
    <dynamics damping="0.5"/>
  </joint>

  <link name="iiwa_link_2">
    <inertial>
      <origin rpy="0 0 0" xyz="0 0 0"/>
      <mass value="6.35"/>
      <inertia ixx="0.0305" ixy="0" ixz="0" iyy="0.0304" iyz="0" izz="0.011"/>
    </inertial>
    <visual>
      <origin rpy="0 0 0" xyz="0 0 0.7"/> 
      <geometry>
        <mesh filename="C:/Users/chiha/OneDrive/Documents/tinyurdf/examples/meshes/link_2_orange.stl"/>
      </geometry>
    </visual>
  </link>

  <joint name="iiwa_joint_3" type="revolute">
    <parent link="iiwa_link_2"/>
    <child link="iiwa_link_3"/>
    <origin rpy="1.5708 0 3.1416" xyz="0 0.7 0.7"/> 
    <axis xyz="0 0 1"/>
    <limit drake:acceleration="8.74" effort="176" lower="-2.96705972839" upper="2.96705972839" velocity="1.7453292519943295"/>
    <dynamics damping="0.5"/>
  </joint>

  <link name="iiwa_link_3">
    <inertial>
      <origin rpy="0 0 0" xyz="0 0 0"/>
      <mass value="3.5"/>
      <inertia ixx="0.025" ixy="0" ixz="0" iyy="0.0238" iyz="0" izz="0.0076"/>
    </inertial>
    <visual>
      <origin rpy="0 0 0" xyz="0 0.7 0.7"/> 
      <geometry>
        <mesh filename="C:/Users/chiha/OneDrive/Documents/tinyurdf/examples/meshes/link_3.stl"/>
      </geometry>
    </visual>
  </link>

  <joint name="iiwa_joint_4" type="revolute">
    <parent link="iiwa_link_3"/>
    <child link="iiwa_link_4"/>
    <origin rpy="1.5708 0 0" xyz="0 1.0 1.2"/> 
    <axis xyz="0 0 1"/>
    <limit drake:acceleration="11.36" effort="176" lower="-2.09439510239" upper="2.09439510239" velocity="1.3089969389957472"/>
    <dynamics damping="0.5"/>
  </joint>

  <link name="iiwa_link_4">
    <inertial>
      <origin rpy="0 0 0" xyz="0 0 0"/>
      <mass value="3.5"/>
      <inertia ixx="0.017" ixy="0" ixz="0" iyy="0.0164" iyz="0" izz="0.006"/>
    </inertial>
    <visual>
      <origin rpy="0 0 0" xyz="0 1.0 1.2"/> 
      <geometry>
        <mesh filename="C:/Users/chiha/OneDrive/Documents/tinyurdf/examples/meshes/link_4_orange.stl"/>
      </geometry>
    </visual>
  </link>

  <joint name="iiwa_joint_5" type="revolute">
    <parent link="iiwa_link_4"/>
    <child link="iiwa_link_5"/>
    <origin rpy="-1.5708 3.1416 0" xyz="0 1.2 1.6"/> 
    <axis xyz="0 0 1"/>
    <limit drake:acceleration="12.23" effort="110" lower="-2.96705972839" upper="2.96705972839" velocity="2.2689280275926285"/>
    <dynamics damping="0.5"/>
  </joint>

  <link name="iiwa_link_5">
    <inertial>
      <origin rpy="0 0 0" xyz="0 0 0"/>
      <mass value="3.5"/>
      <inertia ixx="0.01" ixy="0" ixz="0" iyy="0.0087" iyz="0" izz="0.00449"/>
    </inertial>
    <visual>
      <origin rpy="0 0 0" xyz="0 1.2 1.6"/> 
      <geometry>
        <mesh filename="C:/Users/chiha/OneDrive/Documents/tinyurdf/examples/meshes/link_5.stl"/>
      </geometry>
    </visual>
  </link>

  <joint name="iiwa_joint_6" type="revolute">
    <parent link="iiwa_link_5"/>
    <child link="iiwa_link_6"/>
    <origin rpy="1.5708 0 0" xyz="0 1.5 1.9"/> 
    <axis xyz="0 0 1"/>
    <limit drake:acceleration="15.72" effort="40" lower="-2.09439510239" upper="2.09439510239" velocity="2.356194490192345"/>
    <dynamics damping="0.5"/>
  </joint>

  <link name="iiwa_link_6">
    <inertial>
      <origin rpy="0 0 0" xyz="0 0 0"/>
      <mass value="1.8"/>
      <inertia ixx="0.0049" ixy="0" ixz="0" iyy="0.0047" iyz="0" izz="0.0036"/>
    </inertial>
    <visual>
      <origin rpy="0 0 0" xyz="0 1.5 1.9"/> 
      <geometry>
        <mesh filename="C:/Users/chiha/OneDrive/Documents/tinyurdf/examples/meshes/link_6_orange.stl"/>
      </geometry>
    </visual>
  </link>

</robot>
