<?xml version="1.0" ?>
<!-- =================================================================================== -->
<!-- |    This document was autogenerated by xacro from robot.urdf.xacro               | -->
<!-- |    EDITING THIS FILE BY HAND IS NOT RECOMMENDED                                 | -->
<!-- =================================================================================== -->
<robot name="lwa4p">

  <link name="arm_podest_link">
    <inertial>
      <mass value="0.01"/>
      <origin xyz="0 0 0"/>
      <inertia ixx="0.001" ixy="0.0" ixz="0.0" iyy="0.001" iyz="0.0" izz="0.001"/>
    </inertial>
    <visual>
      <origin rpy="0 3.14159265359 0" xyz="0 0 0.01"/>
      <geometry>
        <mesh filename="C:/Users/chiha/OneDrive/Documents/tinyurdf/examples/meshes/arm_base_link.stl"/>
      </geometry>
    </visual>
    <collision>
      <origin rpy="0 3.14159265359 0" xyz="0 0 0"/>
      <geometry>
        <mesh filename="C:/Users/chiha/OneDrive/Documents/tinyurdf/examples/meshes/arm_base_link.stl"/>
      </geometry>
    </collision>
  </link>
 
   <joint name="arm_podest_joint" type="fixed">
    <origin rpy="0 0 0" xyz="0 0 0.052"/>
    <parent link="world"/>
    <child link="arm_podest_link"/>
  </joint>

  <joint name="arm_base_joint" type="fixed">
    <origin rpy="0 0 0" xyz="0 0 0.10"/>
    <parent link="arm_podest_link"/>
    <child link="arm_base_link"/>
  </joint>

  <link name="arm_base_link">
    <inertial>
      <mass value="0.01"/>
      <origin xyz="0 0 0"/>
      <inertia ixx="0.001" ixy="0.0" ixz="0.0" iyy="0.001" iyz="0.0" izz="0.001"/>
    </inertial>
        <visual>
      <origin rpy="0 3.14159265359 0" xyz="0 0 0.01"/>
      <geometry>
        <mesh filename="C:/Users/chiha/OneDrive/Documents/tinyurdf/examples/meshes/arm_base_link.stl"/>
      </geometry>
    </visual>
    <collision>
      <origin rpy="0 3.14159265359 0" xyz="0 0 0"/>
      <geometry>
        <mesh filename="C:/Users/chiha/OneDrive/Documents/tinyurdf/examples/meshes/arm_base_link.stl"/>
      </geometry>
    </collision>
  </link>

  <joint name="arm_1_joint" type="revolute">
    <origin rpy="0 0 0" xyz="0 0 0"/>
    <parent link="arm_base_link"/>
    <child link="arm_1_link"/>
    <axis xyz="0 0 1"/>
    <limit effort="370" lower="-2.94" upper="2.94" velocity="2.0"/>
    <safety_controller k_position="20" k_velocity="50" soft_lower_limit="${-6.28 + 0.01}" soft_upper_limit="${6.28 - 0.01}"/>
  </joint>

  <link name="arm_1_link">
    <inertial>
      <mass value="0.01"/>
      <origin xyz="0 0 0"/>
      <inertia ixx="0.001" ixy="0.0" ixz="0.0" iyy="0.001" iyz="0.0" izz="0.001"/>
    </inertial>
    <visual>
      <origin rpy="0 0 0" xyz="0 0 0.1"/>
      <geometry>
        <mesh filename="C:/Users/chiha/OneDrive/Documents/tinyurdf/examples/meshes/arm_1_link.stl"/>
      </geometry>
    </visual>
    <collision>
      <origin rpy="0 0 0" xyz="0 0 0"/>
      <geometry>
        <mesh filename="C:/Users/chiha/OneDrive/Documents/tinyurdf/examples/meshes/arm_1_link.stl"/>
      </geometry>
    </collision>
  </link>

  <joint name="arm_2_joint" type="revolute">
    <origin rpy="1.5708 0 0" xyz="0 0 0"/>
    <parent link="arm_1_link"/>
    <child link="arm_2_link"/>
    <axis xyz="0 0 1"/>
    <limit effort="370" lower="-2.94" upper="2.94" velocity="2.0"/>
    <safety_controller k_position="20" k_velocity="50" soft_lower_limit="${-2.09 + 0.01}" soft_upper_limit="${2.09 - 0.01}"/>
  </joint>

  <link name="arm_2_link">
    <inertial>
      <mass value="0.01"/>
      <origin xyz="0 0 0"/>
      <inertia ixx="0.001" ixy="0.0" ixz="0.0" iyy="0.001" iyz="0.0" izz="0.001"/>
    </inertial>
    <visual>
      <origin rpy="0 0 0" xyz="1 0 0.1"/>
      <geometry>
        <mesh filename="C:/Users/chiha/OneDrive/Documents/tinyurdf/examples/meshes/arm_2_link.stl"/>
      </geometry>
    </visual>
    <collision>
      <origin rpy="0 0 0" xyz="0 0 0"/>
      <geometry>
        <mesh filename="C:/Users/chiha/OneDrive/Documents/tinyurdf/examples/meshes/arm_2_link.stl"/>
      </geometry>
    </collision>
  </link>

  <joint name="arm_3_joint" type="revolute">
    <origin rpy="0 3.14159 0" xyz="0 0.350 0"/>
    <parent link="arm_2_link"/>
    <child link="arm_3_link"/>
    <axis xyz="0 0 1"/>
    <limit effort="176" lower="-2.68" upper="2.68" velocity="2.0"/>
    <safety_controller k_position="20" k_velocity="25" soft_lower_limit="${-6.28 + 0.01}" soft_upper_limit="${6.28 - 0.01}" />
  </joint>

  <link name="arm_3_link">
    <inertial>
      <mass value="0.01"/>
      <origin xyz="0 0 0"/>
      <inertia ixx="0.001" ixy="0.0" ixz="0.0" iyy="0.001" iyz="0.0" izz="0.001"/>
    </inertial>
    <visual>
      <origin rpy="0 0 0" xyz="0 1 0.05"/>
      <geometry>
        <mesh filename="C:/Users/chiha/OneDrive/Documents/tinyurdf/examples/meshes/arm_3_link.stl"/>
      </geometry>
    </visual>
    <collision>
      <origin rpy="0 0 0" xyz="0 0 0"/>
      <geometry>
        <mesh filename="C:/Users/chiha/OneDrive/Documents/tinyurdf/examples/meshes/arm_3_link.stl"/>
      </geometry>
    </collision>
  </link>

  <joint name="arm_4_joint" type="revolute">
    <origin rpy="-1.5708 3.14159 0" xyz="0 0 0"/>
    <parent link="arm_3_link"/>
    <child link="arm_4_link"/>
    <axis xyz="0 0 1"/>
    <limit effort="176" lower="-2.94" upper="2.94" velocity="2.0"/>
    <safety_controller k_position="20" k_velocity="25" soft_lower_limit="${-2.09 + 0.01}" soft_upper_limit="${2.09 - 0.01}" />
  </joint>

  <link name="arm_4_link">
    <inertial>
      <mass value="0.01"/>
      <origin xyz="0 0 0"/>
      <inertia ixx="0.001" ixy="0.0" ixz="0.0" iyy="0.001" iyz="0.0" izz="0.001"/>
    </inertial>
    <visual>
      <origin rpy="0 0 0" xyz="0 0 0.8"/>
      <geometry>
        <mesh filename="C:/Users/chiha/OneDrive/Documents/tinyurdf/examples/meshes/arm_4_link.stl"/>
      </geometry>
    </visual>
    <collision>
      <origin rpy="0 0 0" xyz="0 0 0"/>
      <geometry>
        <mesh filename="C:/Users/chiha/OneDrive/Documents/tinyurdf/examples/meshes/arm_4_link.stl"/>
      </geometry>
    </collision>
  </link>

  <joint name="arm_5_joint" type="revolute">
    <origin rpy="1.5708 0 3.14159" xyz="0 0.005263 0.305"/>
    <parent link="arm_4_link"/>
    <child link="arm_5_link"/>
    <axis xyz="0 0 1"/>
    <limit effort="41.6" lower="-2.94" upper="2.94" velocity="2.0"/>
    <safety_controller k_position="20" k_velocity="25" soft_lower_limit="${-6.28 + 0.01}" soft_upper_limit="${6.28 - 0.01}" />
  </joint>

  <link name="arm_5_link">
    <inertial>
      <mass value="0.01"/>
      <origin xyz="0 0 0"/>
      <inertia ixx="0.001" ixy="0.0" ixz="0.0" iyy="0.001" iyz="0.0" izz="0.001"/>
    </inertial>
    <visual>
      <origin rpy="0 0.3 0" xyz="1 0 0.05"/>
      <geometry>
        <mesh filename="C:/Users/chiha/OneDrive/Documents/tinyurdf/examples/meshes/arm_5_link.stl"/>
      </geometry>
    </visual>
    <collision>
      <origin rpy="0.85 0 0" xyz="1 0 0"/>
      <geometry>
        <mesh filename="C:/Users/chiha/OneDrive/Documents/tinyurdf/examples/meshes/arm_5_link.stl"/>
      </geometry>
    </collision>
  </link>

  <joint name="arm_6_joint" type="revolute">
    <origin rpy="-1.5708 0 0" xyz="0 0 0"/>
    <parent link="arm_5_link"/>
    <child link="arm_6_link"/>
    <axis xyz="0 0 1"/>
    <limit effort="20.1" lower="-2.94" upper="2.94" velocity="2.0"/>
    <safety_controller k_position="20" k_velocity="25" soft_lower_limit="${-2.09 + 0.01}" soft_upper_limit="${2.09 - 0.01}" />
  </joint>

  <link name="arm_6_link">
    <inertial>
      <mass value="0.01"/>
      <origin xyz="0 0 0"/>
      <inertia ixx="0.001" ixy="0.0" ixz="0.0" iyy="0.001" iyz="0.0" izz="0.001"/>
    </inertial>
    <visual>
      <origin rpy="0 -0.2 0" xyz="0 1 0.1"/>
      <geometry>
        <mesh filename="C:/Users/chiha/OneDrive/Documents/tinyurdf/examples/meshes/arm_6_link.stl"/>
      </geometry>
    </visual>
    <collision>
      <origin rpy="0 0 0" xyz="0 0 0"/>
      <geometry>
        <mesh filename="C:/Users/chiha/OneDrive/Documents/tinyurdf/examples/meshes/arm_6_link.stl"/>
      </geometry>
    </collision>
  </link>

  <joint name="pg70_palm_joint" type="fixed">
    <parent link="arm_6_link"/>
    <child link="pg70_palm_link"/>
    <origin rpy="0 0 0" xyz="0 0 0.075"/>
  </joint>

  <joint name="pg70_finger_left_joint" type="prismatic">
    <parent link="pg70_palm_link"/>
    <child link="pg70_finger_left_link"/>
    <limit effort="100" lower="0.03" upper="0.114" velocity="2.0"/>
    <origin rpy="0 0 0" xyz="0 0 0.0789"/>
    <axis xyz="0 1 0"/>
  </joint>

  <joint name="pg70_finger_right_joint" type="prismatic">
    <mimic joint="pg70_finger_left_joint" multiplier="1" offset="0"/>
    <parent link="pg70_palm_link"/>
    <child link="pg70_finger_right_link"/>
    <limit effort="100" lower="0.02" upper="1.14" velocity="2.0"/>
    <origin rpy="-0 0 0" xyz="0 0 0.0789"/>
    <axis xyz="0 -1 0"/>
  </joint>
</robot>
