<?xml version="1.0" encoding="utf-8"?>
<!-- =================================================================================== -->
<!-- |    This document was autogenerated by xacro from urdf/spot.urdf.xacro           | -->
<!-- |    EDITING THIS FILE BY HAND IS NOT RECOMMENDED                                 | -->
<!-- =================================================================================== -->
<robot name="spot">

  <link name="body">
    <visual>
      <origin xyz="0 0 0" rpy="0 0 0" />
      <geometry>
        <mesh filename="C:/Users/chiha/OneDrive/Documents/tinyurdf/examples/meshes/body.stl" scale= "1 1 1"/>
      </geometry>
    </visual>
    <collision>
      <geometry>
        <mesh filename="C:/Users/chiha/OneDrive/Documents/tinyurdf/examples/meshes/body_collision.stl"/>
      </geometry>
    </collision>
  </link>

  <joint name="base_link_joint" type="fixed">
    <origin rpy="0 0 0" xyz="0 0 0.05"/>
    <parent link="body"/>
    <child link="base_link"/>
    <axis xyz="0 0 1"/>
    <limit effort="39" velocity="1.3963"/>
    <calibration rising="0.158" falling ="25888.0" reference_position="555"/>
    <mimic joint = "joint_51" offset ="256.0" multiplier = "5.0" />
    <dynamics damping="333.0" friction="1.258.0" inertia="111"/>
    <safety_controller k_velocity="10" k_position="15" soft_lower_limit="-2.0" soft_upper_limit="0.5"/>
  </joint>

  <joint name="front_rail_joint" type="fixed">
    <origin rpy="0 0 0" xyz="0.5 0 0.55" />
    <parent link="body"/>
    <child link="front_rail"/>
  </joint>

  <joint name="real_front_rail_joint" type="fixed">
    <origin rpy="0 0 0" xyz="-0.5 0.5 0.25" />
    <parent link="body"/>
    <child link="real_front_rail"/>
  </joint>

  <joint name="rear_rail_joint" type="fixed">
    <origin rpy="0 0 0" xyz="-0.5 0.5 0.1" />
    <parent link="body"/>
    <child link="rear_rail"/>
  </joint>

  <joint name="real_rear_rail_joint" type="fixed">
    <origin rpy="0 0 0" xyz="-0.5 -0.5 0" />
    <parent link="real_front_rail"/>
    <child link="real_rear_rail"/>
  </joint>

  <link name="front_left_hip">
    <visual>
      <origin xyz="0.3 0.00 0" rpy="0 0 0" />
      <geometry>
        <mesh filename="C:/Users/chiha/OneDrive/Documents/tinyurdf/examples/meshes/front_left_hip.stl" scale="4 2 2"/>
      </geometry>
    </visual>
    <collision>
      <geometry>
        <mesh filename="C:/Users/chiha/OneDrive/Documents/tinyurdf/examples/meshes/front_left_hip_collision.stl"/>
      </geometry>
    </collision>
  </link>

  <joint name="front_left_hip_x" type="revolute">
    <origin rpy="0 0 0" xyz="0.3 0.25 0" />
    <axis xyz="1 0 0"/>
    <parent link="body"/>
    <child link="front_left_hip"/>
    <limit effort="1000" lower="-0.78539816339744827899" upper="0.78539816339744827899" velocity="1000.00"/>
  </joint>

  <link name="front_left_upper_leg">
    <visual>
      <origin xyz="0.3 0.1 0.0" rpy="0 0 0" />
      <geometry>
        <mesh filename="C:/Users/chiha/OneDrive/Documents/tinyurdf/examples/meshes/front_left_upper_leg.stl"/>
      </geometry>
    </visual>
    <collision>
      <geometry>
        <mesh filename="C:/Users/chiha/OneDrive/Documents/tinyurdf/examples/meshes/front_left_upper_leg_collision.stl"/>
      </geometry>
    </collision>
  </link>

  <joint name="front_left_hip_y" type="revolute">
    <origin rpy="0 0 0" xyz="0.5 0.15 0.1" />
    <axis xyz="0 1 0"/>
    <parent link="front_left_hip"/>
    <child link="front_left_upper_leg"/>
    <limit effort="1000" lower="-0.89884456477707963539" upper="2.2951079663725435509" velocity="1000.00"/>
  </joint>

  <link name="front_left_lower_leg">
    <visual>
      <origin xyz="0.3 0.1 -0.3" rpy="0 0 0" />
      <geometry>
        <mesh filename="C:/Users/chiha/OneDrive/Documents/tinyurdf/examples/meshes/front_left_lower_leg.stl"/>
      </geometry>
    </visual>
    <collision>
      <geometry>
        <mesh filename="C:/Users/chiha/OneDrive/Documents/tinyurdf/examples/meshes/front_left_lower_leg_collision.stl"/>
      </geometry>
    </collision>
  </link>

  <joint name="front_left_knee" type="revolute">
    <origin rpy="0 0 0" xyz="0.6 0.1 -0.25" />
    <axis xyz="0 1 0"/>
    <parent link="front_left_upper_leg"/>
    <child link="front_left_lower_leg"/>
    <limit effort="1000" lower="-2.7929" upper="-0.254801" velocity="1000.00"/>
  </joint>

  <link name="front_right_hip">
    <visual>
      <origin xyz="-0.3 0.05 0" rpy="0 0 0" />
      <geometry>
        <mesh filename="C:/Users/chiha/OneDrive/Documents/tinyurdf/examples/meshes/front_right_hip.stl"/>
      </geometry>
    </visual>
    <collision>
      <geometry>
        <mesh filename="C:/Users/chiha/OneDrive/Documents/tinyurdf/examples/meshes/front_right_hip_collision.stl"/>
      </geometry>
    </collision>
  </link>
  
  <joint name="front_right_hip_x" type="revolute">
    <origin rpy="0 0 0" xyz="0.3 -0.25 0" />
    <axis xyz="1 0 0"/>
    <parent link="body"/>
    <child link="front_right_hip"/>
    <limit effort="1000" lower="-0.78539816339744827899" upper="0.78539816339744827899" velocity="1000.00"/>
  </joint>

  <link name="front_right_upper_leg">
    <visual>
      <origin xyz="0.3 -0.1 -0.0" rpy="0 0 0" />
      <geometry>
        <mesh filename="C:/Users/chiha/OneDrive/Documents/tinyurdf/examples/meshes/front_right_upper_leg.stl"/>
      </geometry>
    </visual>
    <collision>
      <geometry>
        <mesh filename="C:/Users/chiha/OneDrive/Documents/tinyurdf/examples/meshes/front_right_upper_leg_collision.stl"/>
      </geometry>
    </collision>
  </link>

  <joint name="front_right_hip_y" type="revolute">
    <origin rpy="0 0 0" xyz="0.5 -0.15 0.1" />
    <axis xyz="0 1 0"/>
    <parent link="front_right_hip"/>
    <child link="front_right_upper_leg"/>
    <limit effort="1000" lower="-0.89884456477707963539" upper="2.2951079663725435509" velocity="1000.00"/>
  </joint>

  <link name="front_right_lower_leg">
    <visual>
      <origin xyz="0.3 -0.1 -0.3" rpy="0 0 0" />
      <geometry>
        <mesh filename="C:/Users/chiha/OneDrive/Documents/tinyurdf/examples/meshes/front_right_lower_leg.stl"/>
      </geometry>
    </visual>
    <collision>
      <geometry>
        <mesh filename="C:/Users/chiha/OneDrive/Documents/tinyurdf/examples/meshes/front_right_lower_leg_collision.stl"/>
      </geometry>
    </collision>
  </link>

  <joint name="front_right_knee" type="revolute">
    <origin rpy="0 0 0" xyz="0.6 -0.1 -0.25" />
    <axis xyz="0 1 0"/>
    <parent link="front_right_upper_leg"/>
    <child link="front_right_lower_leg"/>
    <limit effort="1000" lower="-2.7929" upper="-0.247563" velocity="1000.00"/>
  </joint>

  <link name="rear_left_hip">
    <visual>
       <origin xyz="-0.3 0.00 0" rpy="0 0 0" />
      <geometry>
        <mesh filename="C:/Users/chiha/OneDrive/Documents/tinyurdf/examples/meshes/rear_left_hip.stl"/>
      </geometry>
    </visual>
    <collision>
      <geometry>
        <mesh filename="C:/Users/chiha/OneDrive/Documents/tinyurdf/examples/meshes/rear_left_hip_collision.stl"/>
      </geometry>
    </collision>
  </link>

  <joint name="rear_left_hip_x" type="revolute">
    <origin rpy="0 0 0" xyz="-0.3 0.2 0" />
    <axis xyz="1 0 0"/>
    <parent link="body"/>
    <child link="rear_left_hip"/>
    <limit effort="1000" lower="-0.78539816339744827899" upper="0.78539816339744827899" velocity="1000.00"/>
  </joint>

  <link name="rear_left_upper_leg">
    <visual>
      <origin xyz="-0.3 0.1 0.0" rpy="0 0 0" />
      <geometry>
        <mesh filename="C:/Users/chiha/OneDrive/Documents/tinyurdf/examples/meshes/rear_left_upper_leg.stl"/>
      </geometry>
    </visual>
    <collision>
      <geometry>
        <mesh filename="C:/Users/chiha/OneDrive/Documents/tinyurdf/examples/meshes/rear_left_upper_leg_collision.stl"/>
      </geometry>
    </collision>
  </link>

  <joint name="rear_left_hip_y" type="revolute">
    <origin rpy="0 0 0" xyz="-0.5 0.15 0.1" />
    <axis xyz="0 1 0"/>
    <parent link="rear_left_hip"/>
    <child link="rear_left_upper_leg"/>
    <limit effort="1000" lower="-0.89884456477707963539" upper="2.2951079663725435509" velocity="1000.00"/>
  </joint>

  <link name="rear_left_lower_leg">
    <visual>
      <origin xyz="-0.3 0.1 -0.3" rpy="0 0 0" />
      <geometry>
        <mesh filename="C:/Users/chiha/OneDrive/Documents/tinyurdf/examples/meshes/rear_left_lower_leg.stl"/>
      </geometry>
    </visual>
    <collision>
      <geometry>
        <mesh filename="C:/Users/chiha/OneDrive/Documents/tinyurdf/examples/meshes/rear_left_lower_leg_collision.stl"/>
      </geometry>
    </collision>
  </link>

  <joint name="rear_left_knee" type="revolute">
    <origin rpy="0 0 0" xyz="-0.6 0.1 -0.25" />
    <axis xyz="0 1 0"/>
    <parent link="rear_left_upper_leg"/>
    <child link="rear_left_lower_leg"/>
    <limit effort="1000" lower="-2.7929" upper="-0.267153" velocity="1000.00"/>
  </joint>

  <link name="rear_right_hip">
    <visual>
      <origin xyz="-0.3 -0.05 0" rpy="0 0 0" />
      <geometry>
        <mesh filename="C:/Users/chiha/OneDrive/Documents/tinyurdf/examples/meshes/rear_right_hip.stl"/>
      </geometry>
    </visual>
    <collision>
      <geometry>
        <mesh filename="C:/Users/chiha/OneDrive/Documents/tinyurdf/examples/meshes/rear_right_hip_collision.stl"/>
      </geometry>
    </collision>
  </link>

  <joint name="rear_right_hip_x" type="revolute">
    <origin rpy="0 0 0" xyz="-0.3 -0.2 0" />
    <axis xyz="1 0 0"/>
    <parent link="body"/>
    <child link="rear_right_hip"/>
    <limit effort="1000" lower="-0.78539816339744827899" upper="0.78539816339744827899" velocity="1000.00"/>
  </joint>

  <link name="rear_right_upper_leg">
    <visual>
      <origin xyz="-0.3 -0.1 -0.0" rpy="0 0 0" />
      <geometry>
        <mesh filename="C:/Users/chiha/OneDrive/Documents/tinyurdf/examples/meshes/rear_right_upper_leg.stl"/>
      </geometry>
    </visual>
    <collision>
      <geometry>
        <mesh filename="C:/Users/chiha/OneDrive/Documents/tinyurdf/examples/meshes/rear_right_upper_leg_collision.stl"/>
      </geometry>
    </collision>
  </link>

  <joint name="rear_right_hip_y" type="revolute">
    <origin rpy="0 0 0" xyz="-0.5 -0.15 0.1" />
    <axis xyz="0 1 0"/>
    <parent link="rear_right_hip"/>
    <child link="rear_right_upper_leg"/>
    <limit effort="1000" lower="-0.89884456477707963539" upper="2.2951079663725435509" velocity="1000.00"/>
  </joint>

  <link name="rear_right_lower_leg">
    <visual>
      <origin xyz="-0.3 -0.1 -0.3" rpy="0 0 0" />
      <geometry>
        <mesh filename="C:/Users/chiha/OneDrive/Documents/tinyurdf/examples/meshes/rear_right_lower_leg.stl"/>
      </geometry>
    </visual>
    <collision>
      <geometry>
        <mesh filename="C:/Users/chiha/OneDrive/Documents/tinyurdf/examples/meshes/rear_right_lower_leg_collision.stl"/>
      </geometry>
    </collision>
  </link>

  <joint name="rear_right_knee" type="revolute">
    <origin rpy="0 0 0" xyz="-0.6 -0.1 -0.25" />
    <axis xyz="0 1 0"/>
    <parent link="rear_right_upper_leg"/>
    <child link="rear_right_lower_leg"/>
    <limit effort="1000" lower="-2.7929" upper="-0.257725" velocity="1000.00"/>
  </joint>

</robot>